<?xml version="1.0" ?>
<sdf version="1.5">
  <model name="wheel_valve_large_wall">
  
    <link name="wall">
      <inertial>
        <pose>0.6096 0.00476 1.2192 0 0 0</pose>
        <mass>2.5</mass>
        <inertia>
          <ixx>1.23872608133</ixx>
          <ixy>0</ixy>
          <ixz>0</ixz>
          <iyy>1.548384</iyy>
          <iyz>0</iyz>
          <izz>0.30969568133</izz>
        </inertia>
      </inertial>

      <collision name="collision">
        <pose>0.6096 0.00476 1.2192 0 0 0</pose>
        <geometry>
          <box>
            <size>1.2192 0.00952 2.4384</size>
          </box>
        </geometry>
      </collision>
      <visual name="visual">
        <pose>-0.004536186 -0.003571748 0 0 0 0</pose>
        <geometry>
          <mesh>
            <uri>model://drc_practice_valve_wall/meshes/five_dice_wall.dae</uri>
          </mesh>
        </geometry>
      </visual>
    </link>
    
    <joint name="wall-joint" type="fixed">
      <parent>world</parent>
      <child>wall</child>
    </joint>
    
    <link name="valve">
      <pose>0.614335 -0.0092 1.2 0 0 0</pose>
      <inertial>
        <mass>7.8219</mass>
        <pose>0 0.0615 0 0 0 0</pose>
        <inertia>
          <ixx>0.0695</ixx>
          <ixy>0.0000</ixy>
          <ixz>0.0000</ixz>
          <iyy>0.1349</iyy>
          <iyz>0.0000</iyz>
          <izz>0.0695</izz>
        </inertia>
      </inertial>
      <collision name="collision">
        <geometry>
          <mesh>
            <uri>model://drc_practice_wheel_valve_large/meshes/wheel_valve_large.dae</uri>
          </mesh>
        </geometry>
        <surface>
          <friction>
            <ode>
              <mu>1</mu>
              <mu2>1</mu2>
            </ode>
          </friction>
          <contact>
            <ode>
              <kp>1000000.0</kp>
              <kd>100.0</kd>
              <max_vel>0.01</max_vel>
              <min_depth>0.001</min_depth>
            </ode>
          </contact>
        </surface>
      </collision>
      <visual name="visual">
        <geometry>
          <mesh>
            <uri>model://drc_practice_wheel_valve_large/meshes/wheel_valve_large.dae</uri>
          </mesh>
        </geometry>
      </visual>
    </link>>
    <joint name="joint" type="revolute">
      <parent>wall</parent>
      <child>valve</child>
      <axis>
        <xyz>0 1 0</xyz>
        <limit>
          <lower>-12.56</lower>
          <upper>12.56</upper>
        </limit>
        <dynamics>
          <!--velocity dependent viscous damping coefficient of the joint-->
          <damping>0.1</damping>
          <!--default 0, static friction value of the joint-->
          <friction>0.1</friction>
        </dynamics>
        <use_parent_model_frame>false</use_parent_model_frame>
      </axis>
      <physics>
        <ode>
          <implicit_spring_damper>1</implicit_spring_damper>
        </ode>
      </physics>
    </joint>
  </model>
</sdf>
