<?xml version='1.0'?>
<sdf version='1.7'>
  <model name='Wardrobe'>
    <link name='wardrobe'>
      <inertial>
        <mass>30.0</mass>
        <inertia>
          <ixx>10.625</ixx>
          <ixy>0</ixy>
          <ixz>0</ixz>
          <iyy>12.5</iyy>
          <iyz>0</iyz>
          <izz>3.125</izz>
        </inertia>
        <pose>0 0 0 0 0 0</pose>
      </inertial>
      <self_collide>0</self_collide>
      <enable_wind>0</enable_wind>
      <kinematic>0</kinematic>
      <pose>0 0 0 0 0 0</pose>
      <visual name='visual_wardrobe'>
        <geometry>
          <mesh>
            <uri>model://Wardrobe/meshes/Wardrobe.dae</uri>
          </mesh>
        </geometry>
        <material>          
          <name>Gazebo/DarkGrey </name>
            <uri>file://media/materials/scripts/gazebo.material</uri>
          </material>
      </visual>
      <collision name='collision_wardrobe'>
        <laser_retro>0</laser_retro>
        <max_contacts>10</max_contacts>
        <pose>0 0 0 0 0 0</pose>
        <geometry>
          <mesh>
            <uri>model://Wardrobe/meshes/Wardrobe.dae</uri>
          </mesh>
        </geometry>
        <surface>
          <friction>
            <ode>
              <mu>0.85</mu>
              <mu2>0.85</mu2>
            </ode>
          </friction>
        </surface>
      </collision>
    </link>
    
    
    <link name='door1'>
      <inertial>
        <mass>1.0</mass>
        <inertia>
          <ixx>0.354166665</ixx>
          <ixy>0</ixy>
          <ixz>0</ixz>
          <iyy>0.416666665</iyy>
          <iyz>0</iyz>
          <izz>0.104166666</izz>
        </inertia>
        <pose>0 0 0 0 0 0</pose>
      </inertial>
      <self_collide>0</self_collide>
      <enable_wind>0</enable_wind>
      <kinematic>0</kinematic>
      <pose>0 0.0 0.0 0 0 0</pose>
      <visual name='visual_door1'>
        <geometry>
          <mesh>
            <uri>model://Wardrobe/meshes/Door.dae</uri>
          </mesh>
        </geometry>
        <material>          
          <name>Gazebo/Grey </name>
            <uri>file://media/materials/scripts/gazebo.material</uri>
          </material>
      </visual>
      <collision name='collision_door1'>
        <laser_retro>0</laser_retro>
        <max_contacts>10</max_contacts>
        <pose>0 0 0 0 0 0</pose>
        <geometry>
          <mesh>
            <uri>model://Wardrobe/meshes/Door.dae</uri>
          </mesh>
        </geometry>
        <surface>
          <friction>
            <ode>
              <mu>0.95</mu>
              <mu2>0.95</mu2>
            </ode>
          </friction>
        </surface>
      </collision>
    </link>
    
    <link name='door2'>
      <inertial>
        <mass>1.0</mass>
        <inertia>
          <ixx>0.354166665</ixx>
          <ixy>0</ixy>
          <ixz>0</ixz>
          <iyy>0.416666665</iyy>
          <iyz>0</iyz>
          <izz>0.104166666</izz>
        </inertia>
        <pose>0 0 0 0 0 0</pose>
      </inertial>
      <self_collide>0</self_collide>
      <enable_wind>0</enable_wind>
      <kinematic>0</kinematic>
      <pose>0 0.0 0.0 0 3.14 0</pose>
      <visual name='visual_door2'>
        <geometry>
          <mesh>
            <uri>model://Wardrobe/meshes/Door.dae</uri>
          </mesh>
        </geometry>
        <material>          
          <name>Gazebo/Grey </name>
            <uri>file://media/materials/scripts/gazebo.material</uri>
          </material>
      </visual>
      <collision name='collision_door2'>
        <laser_retro>0</laser_retro>
        <max_contacts>10</max_contacts>
        <pose>0 0 0 0 0 0</pose>
        <geometry>
          <mesh>
            <uri>model://Wardrobe/meshes/Door.dae</uri>
          </mesh>
        </geometry>
        <surface>
          <friction>
            <ode>
              <mu>0.95</mu>
              <mu2>0.95</mu2>
            </ode>
          </friction>
        </surface>
      </collision>
    </link>
        
    <joint name="jnt_1" type="revolute">
        <parent> wardrobe </parent>
        <child> door1 </child>
        <pose> -0.50 -0.250 0.0 0.0 0.0 0.0 </pose>
        <axis>
            <xyz> 0 0 1</xyz>
            <limit>
                <lower> -1.57 </lower>
                <upper> 0.0 </upper>
            </limit>  
            <dynamics> 
                <friction> 1.0 </friction>
            </dynamics>       
        </axis>
    </joint>
        
    <joint name="jnt_2" type="revolute">
        <parent> wardrobe </parent>
        <child> door2 </child>
        <pose> -0.50 -0.25 0.0 0.0 0.0 0.0 </pose>
        <axis>
            <xyz> 0 0 1</xyz>
            <limit>
                <lower> -1.57 </lower>
                <upper> 0.0 </upper>
            </limit>    
            <dynamics> 
                <friction> 1.0 </friction>
            </dynamics>     
        </axis>
    </joint>
        
    
  </model>
</sdf>
